<mujoco model="5dof_arm">
    <compiler angle="degree"/>
    <option gravity="0 0 -9.81"/>

    <worldbody>
        <!-- Base --> 
		<light diffuse=".5 .5 .5" pos="0 0 10" dir="0 0 -1"/>
		<geom type="plane" size="5 5 0.1" rgba=".9 .9 .9 1"/>
        <body name="base" pos="0 0 0.1">
            <geom type="cylinder" size="0.05 0.1" rgba="0.6 0.6 0.6 1"/>
            
            <!-- Joint 1: rotation around z -->
            <body name="link1" pos="0 0 0.1">
                <joint name="joint1" type="hinge" axis="0 0 1" limited="true" range="-180 180"/>
                <geom type="capsule" fromto="0 0 0 0 0 0.2" size="0.03" rgba="0.9 0.1 0.1 1"/>
				  <!-- Joint 2: rotation around y -->
                <body name="link2" pos="0 0 0.2">
                    <joint name="joint2" type="hinge" axis="0 1 0" limited="true" range="-180 180"/>
                    <geom type="capsule" fromto="0 0 0 0 0 0.2" size="0.025" rgba="0.1 0.9 0.1 1"/>
				</body>
            </body>
		</body>
      
    </worldbody>

    <actuator>
        <position joint="joint1" kp="50"/>
		<position joint="joint2" kp="50"/>
    </actuator>
</mujoco>
